2022-08-13 19:39:36,885 INFO    StreamThr :13684 [internal.py:wandb_internal():93] W&B internal server running at pid: 13684, started at: 2022-08-13 19:39:36.885634
2022-08-13 19:39:36,899 DEBUG   HandlerThread:13684 [handler.py:handle_request():141] handle_request: status
2022-08-13 19:39:36,901 DEBUG   SenderThread:13684 [sender.py:send_request():316] send_request: status
2022-08-13 19:39:36,914 DEBUG   SenderThread:13684 [sender.py:send():302] send: header
2022-08-13 19:39:36,914 INFO    WriterThread:13684 [datastore.py:open_for_write():75] open: F:\KD project\Reused Teacher Classifier\SimKD-S\wandb\run-20220813_193936-hgisim4g\run-hgisim4g.wandb
2022-08-13 19:39:36,962 DEBUG   SenderThread:13684 [sender.py:send():302] send: run
2022-08-13 19:39:37,798 ERROR   SenderThread:13684 [internal_api.py:execute():207] 404 response executing GraphQL.
2022-08-13 19:39:37,798 ERROR   SenderThread:13684 [internal_api.py:execute():208] {"errors":[{"message":"project not found","path":["upsertBucket"]}],"data":{"upsertBucket":null}}
2022-08-13 19:39:37,968 INFO    WriterThread:13684 [datastore.py:close():279] close: F:\KD project\Reused Teacher Classifier\SimKD-S\wandb\run-20220813_193936-hgisim4g\run-hgisim4g.wandb
2022-08-13 19:39:37,968 INFO    HandlerThread:13684 [handler.py:finish():810] shutting down handler
2022-08-13 19:39:37,968 ERROR   StreamThr :13684 [internal.py:wandb_internal():165] Thread SenderThread:
Traceback (most recent call last):
  File "D:\Anaconda\envs\simkd\lib\site-packages\wandb\sdk\lib\retry.py", line 113, in __call__
    result = self._call_fn(*args, **kwargs)
  File "D:\Anaconda\envs\simkd\lib\site-packages\wandb\sdk\internal\internal_api.py", line 204, in execute
    return self.client.execute(*args, **kwargs)  # type: ignore
  File "D:\Anaconda\envs\simkd\lib\site-packages\wandb\vendor\gql-0.2.0\wandb_gql\client.py", line 52, in execute
    result = self._get_result(document, *args, **kwargs)
  File "D:\Anaconda\envs\simkd\lib\site-packages\wandb\vendor\gql-0.2.0\wandb_gql\client.py", line 60, in _get_result
    return self.transport.execute(document, *args, **kwargs)
  File "D:\Anaconda\envs\simkd\lib\site-packages\wandb\vendor\gql-0.2.0\wandb_gql\transport\requests.py", line 39, in execute
    request.raise_for_status()
  File "D:\Anaconda\envs\simkd\lib\site-packages\requests\models.py", line 1021, in raise_for_status
    raise HTTPError(http_error_msg, response=self)
requests.exceptions.HTTPError: 404 Client Error: Not Found for url: https://api.wandb.ai/graphql

During handling of the above exception, another exception occurred:

Traceback (most recent call last):
  File "D:\Anaconda\envs\simkd\lib\site-packages\wandb\apis\normalize.py", line 25, in wrapper
    return func(*args, **kwargs)
  File "D:\Anaconda\envs\simkd\lib\site-packages\wandb\sdk\internal\internal_api.py", line 1469, in upsert_run
    **kwargs,
  File "D:\Anaconda\envs\simkd\lib\site-packages\wandb\sdk\lib\retry.py", line 129, in __call__
    retry_timedelta_triggered = check_retry_fn(e)
  File "D:\Anaconda\envs\simkd\lib\site-packages\wandb\util.py", line 942, in check_retry_fn
    return fallback_retry_fn(e)
  File "D:\Anaconda\envs\simkd\lib\site-packages\wandb\util.py", line 889, in no_retry_auth
    raise CommError("Permission denied, ask the project owner to grant you access")
wandb.errors.CommError: Permission denied, ask the project owner to grant you access

During handling of the above exception, another exception occurred:

Traceback (most recent call last):
  File "D:\Anaconda\envs\simkd\lib\site-packages\wandb\sdk\internal\internal_util.py", line 51, in run
    self._run()
  File "D:\Anaconda\envs\simkd\lib\site-packages\wandb\sdk\internal\internal_util.py", line 102, in _run
    self._process(record)
  File "D:\Anaconda\envs\simkd\lib\site-packages\wandb\sdk\internal\internal.py", line 310, in _process
    self._sm.send(record)
  File "D:\Anaconda\envs\simkd\lib\site-packages\wandb\sdk\internal\sender.py", line 304, in send
    send_handler(record)
  File "D:\Anaconda\envs\simkd\lib\site-packages\wandb\sdk\internal\sender.py", line 782, in send_run
    self._init_run(run, config_value_dict)
  File "D:\Anaconda\envs\simkd\lib\site-packages\wandb\sdk\internal\sender.py", line 822, in _init_run
    commit=run.git.commit or None,
  File "D:\Anaconda\envs\simkd\lib\site-packages\wandb\apis\normalize.py", line 61, in wrapper
    raise CommError(message, err).with_traceback(sys.exc_info()[2])
  File "D:\Anaconda\envs\simkd\lib\site-packages\wandb\apis\normalize.py", line 25, in wrapper
    return func(*args, **kwargs)
  File "D:\Anaconda\envs\simkd\lib\site-packages\wandb\sdk\internal\internal_api.py", line 1469, in upsert_run
    **kwargs,
  File "D:\Anaconda\envs\simkd\lib\site-packages\wandb\sdk\lib\retry.py", line 129, in __call__
    retry_timedelta_triggered = check_retry_fn(e)
  File "D:\Anaconda\envs\simkd\lib\site-packages\wandb\util.py", line 942, in check_retry_fn
    return fallback_retry_fn(e)
  File "D:\Anaconda\envs\simkd\lib\site-packages\wandb\util.py", line 889, in no_retry_auth
    raise CommError("Permission denied, ask the project owner to grant you access")
wandb.errors.CommError: Permission denied, ask the project owner to grant you access
